[2024-11-10T13:14:39.666+0000] {taskinstance.py:1979} INFO - Dependencies all met for dep_context=non-requeueable deps ti=<TaskInstance: analytics_pipeline.trip_stop_sensor scheduled__2024-11-10T13:14:35.889396+00:00 [queued]>
[2024-11-10T13:14:39.673+0000] {taskinstance.py:1979} INFO - Dependencies all met for dep_context=requeueable deps ti=<TaskInstance: analytics_pipeline.trip_stop_sensor scheduled__2024-11-10T13:14:35.889396+00:00 [queued]>
[2024-11-10T13:14:39.673+0000] {taskinstance.py:2193} INFO - Starting attempt 1 of 1
[2024-11-10T13:14:39.684+0000] {taskinstance.py:2217} INFO - Executing <Task(RabbitMQSensor): trip_stop_sensor> on 2024-11-10 13:14:35.889396+00:00
[2024-11-10T13:14:39.688+0000] {standard_task_runner.py:60} INFO - Started process 5927 to run task
[2024-11-10T13:14:39.691+0000] {standard_task_runner.py:87} INFO - Running: ['***', 'tasks', 'run', 'analytics_pipeline', 'trip_stop_sensor', 'scheduled__2024-11-10T13:14:35.889396+00:00', '--job-id', '644', '--raw', '--subdir', 'DAGS_FOLDER/analytics_pipeline.py', '--cfg-path', '/tmp/tmpa8tcoirk']
[2024-11-10T13:14:39.692+0000] {standard_task_runner.py:88} INFO - Job 644: Subtask trip_stop_sensor
[2024-11-10T13:14:39.727+0000] {task_command.py:423} INFO - Running <TaskInstance: analytics_pipeline.trip_stop_sensor scheduled__2024-11-10T13:14:35.889396+00:00 [running]> on host 2a2d16a2b1e8
[2024-11-10T13:14:39.786+0000] {taskinstance.py:2513} INFO - Exporting env vars: AIRFLOW_CTX_DAG_OWNER='***' AIRFLOW_CTX_DAG_ID='analytics_pipeline' AIRFLOW_CTX_TASK_ID='trip_stop_sensor' AIRFLOW_CTX_EXECUTION_DATE='2024-11-10T13:14:35.889396+00:00' AIRFLOW_CTX_TRY_NUMBER='1' AIRFLOW_CTX_DAG_RUN_ID='scheduled__2024-11-10T13:14:35.889396+00:00'
[2024-11-10T13:14:39.793+0000] {base.py:83} INFO - Using connection ID 'RabbitMQ' for task execution.
[2024-11-10T13:14:39.795+0000] {connection_workflow.py:179} INFO - Pika version 1.3.2 connecting to ('::1', 5672, 0, 0)
[2024-11-10T13:14:39.796+0000] {io_services_utils.py:349} ERROR - Socket failed to connect: <socket.socket fd=93, family=AddressFamily.AF_INET6, type=SocketKind.SOCK_STREAM, proto=6, laddr=('::1', 49522, 0, 0)>; error=111 (Connection refused)
[2024-11-10T13:14:39.796+0000] {connection_workflow.py:375} ERROR - TCP Connection attempt failed: ConnectionRefusedError(111, 'Connection refused'); dest=(10, 1, 6, '', ('::1', 5672, 0, 0))
[2024-11-10T13:14:39.797+0000] {connection_workflow.py:291} ERROR - AMQPConnector - reporting failure: AMQPConnectorSocketConnectError: ConnectionRefusedError(111, 'Connection refused')
[2024-11-10T13:14:39.797+0000] {connection_workflow.py:179} INFO - Pika version 1.3.2 connecting to ('127.0.0.1', 5672)
[2024-11-10T13:14:39.798+0000] {io_services_utils.py:349} ERROR - Socket failed to connect: <socket.socket fd=93, family=AddressFamily.AF_INET, type=SocketKind.SOCK_STREAM, proto=6, laddr=('127.0.0.1', 53852)>; error=111 (Connection refused)
[2024-11-10T13:14:39.798+0000] {connection_workflow.py:375} ERROR - TCP Connection attempt failed: ConnectionRefusedError(111, 'Connection refused'); dest=(2, 1, 6, '', ('127.0.0.1', 5672))
[2024-11-10T13:14:39.798+0000] {connection_workflow.py:291} ERROR - AMQPConnector - reporting failure: AMQPConnectorSocketConnectError: ConnectionRefusedError(111, 'Connection refused')
[2024-11-10T13:14:39.799+0000] {connection_workflow.py:746} ERROR - AMQP connection workflow failed: AMQPConnectionWorkflowFailed: 2 exceptions in all; last exception - AMQPConnectorSocketConnectError: ConnectionRefusedError(111, 'Connection refused'); first exception - AMQPConnectorSocketConnectError: ConnectionRefusedError(111, 'Connection refused').
[2024-11-10T13:14:39.799+0000] {connection_workflow.py:723} ERROR - AMQPConnectionWorkflow - reporting failure: AMQPConnectionWorkflowFailed: 2 exceptions in all; last exception - AMQPConnectorSocketConnectError: ConnectionRefusedError(111, 'Connection refused'); first exception - AMQPConnectorSocketConnectError: ConnectionRefusedError(111, 'Connection refused')
[2024-11-10T13:14:39.800+0000] {blocking_connection.py:450} ERROR - Connection workflow failed: AMQPConnectionWorkflowFailed: 2 exceptions in all; last exception - AMQPConnectorSocketConnectError: ConnectionRefusedError(111, 'Connection refused'); first exception - AMQPConnectorSocketConnectError: ConnectionRefusedError(111, 'Connection refused')
[2024-11-10T13:14:39.800+0000] {blocking_connection.py:457} ERROR - Error in _create_connection().
Traceback (most recent call last):
  File "/home/airflow/.local/lib/python3.8/site-packages/pika/adapters/blocking_connection.py", line 451, in _create_connection
    raise self._reap_last_connection_workflow_error(error)
pika.exceptions.AMQPConnectionError
[2024-11-10T13:14:39.801+0000] {taskinstance.py:2731} ERROR - Task failed with exception
Traceback (most recent call last):
  File "/home/airflow/.local/lib/python3.8/site-packages/airflow/models/taskinstance.py", line 444, in _execute_task
    result = _execute_callable(context=context, **execute_callable_kwargs)
  File "/home/airflow/.local/lib/python3.8/site-packages/airflow/models/taskinstance.py", line 414, in _execute_callable
    return execute_callable(context=context, **execute_callable_kwargs)
  File "/home/airflow/.local/lib/python3.8/site-packages/rabbitmq_provider/sensors/rabbitmq.py", line 32, in execute
    super().execute(context)
  File "/home/airflow/.local/lib/python3.8/site-packages/airflow/sensors/base.py", line 265, in execute
    raise e
  File "/home/airflow/.local/lib/python3.8/site-packages/airflow/sensors/base.py", line 247, in execute
    poke_return = self.poke(context)
  File "/home/airflow/.local/lib/python3.8/site-packages/rabbitmq_provider/sensors/rabbitmq.py", line 37, in poke
    message = hook.pull(self.queue_name)
  File "/home/airflow/.local/lib/python3.8/site-packages/rabbitmq_provider/hooks/rabbitmq.py", line 123, in pull
    connection = self.get_conn()
  File "/home/airflow/.local/lib/python3.8/site-packages/rabbitmq_provider/hooks/rabbitmq.py", line 56, in get_conn
    connection = pika.BlockingConnection(parameters)
  File "/home/airflow/.local/lib/python3.8/site-packages/pika/adapters/blocking_connection.py", line 360, in __init__
    self._impl = self._create_connection(parameters, _impl_class)
  File "/home/airflow/.local/lib/python3.8/site-packages/pika/adapters/blocking_connection.py", line 451, in _create_connection
    raise self._reap_last_connection_workflow_error(error)
pika.exceptions.AMQPConnectionError
[2024-11-10T13:14:39.806+0000] {taskinstance.py:1149} INFO - Marking task as FAILED. dag_id=analytics_pipeline, task_id=trip_stop_sensor, execution_date=20241110T131435, start_date=20241110T131439, end_date=20241110T131439
[2024-11-10T13:14:39.814+0000] {standard_task_runner.py:107} ERROR - Failed to execute job 644 for task trip_stop_sensor (; 5927)
[2024-11-10T13:14:39.823+0000] {local_task_job_runner.py:234} INFO - Task exited with return code 1
[2024-11-10T13:14:39.844+0000] {taskinstance.py:3312} INFO - 0 downstream tasks scheduled from follow-on schedule check
