[2024-11-10T22:04:37.197+0000] {taskinstance.py:1979} INFO - Dependencies all met for dep_context=non-requeueable deps ti=<TaskInstance: python_broker_postgres.load manual__2024-11-10T22:00:34.275403+00:00 [queued]>
[2024-11-10T22:04:37.204+0000] {taskinstance.py:1979} INFO - Dependencies all met for dep_context=requeueable deps ti=<TaskInstance: python_broker_postgres.load manual__2024-11-10T22:00:34.275403+00:00 [queued]>
[2024-11-10T22:04:37.205+0000] {taskinstance.py:2193} INFO - Starting attempt 1 of 1
[2024-11-10T22:04:37.217+0000] {taskinstance.py:2217} INFO - Executing <Task(_PythonDecoratedOperator): load> on 2024-11-10 22:00:34.275403+00:00
[2024-11-10T22:04:37.221+0000] {standard_task_runner.py:60} INFO - Started process 2524 to run task
[2024-11-10T22:04:37.223+0000] {standard_task_runner.py:87} INFO - Running: ['***', 'tasks', 'run', 'python_broker_postgres', 'load', 'manual__2024-11-10T22:00:34.275403+00:00', '--job-id', '1274', '--raw', '--subdir', 'DAGS_FOLDER/python_broker_postgres.py', '--cfg-path', '/tmp/tmpv5_d7rj_']
[2024-11-10T22:04:37.224+0000] {standard_task_runner.py:88} INFO - Job 1274: Subtask load
[2024-11-10T22:04:37.260+0000] {task_command.py:423} INFO - Running <TaskInstance: python_broker_postgres.load manual__2024-11-10T22:00:34.275403+00:00 [running]> on host 2a2d16a2b1e8
[2024-11-10T22:04:37.314+0000] {taskinstance.py:2513} INFO - Exporting env vars: AIRFLOW_CTX_DAG_OWNER='***' AIRFLOW_CTX_DAG_ID='python_broker_postgres' AIRFLOW_CTX_TASK_ID='load' AIRFLOW_CTX_EXECUTION_DATE='2024-11-10T22:00:34.275403+00:00' AIRFLOW_CTX_TRY_NUMBER='1' AIRFLOW_CTX_DAG_RUN_ID='manual__2024-11-10T22:00:34.275403+00:00'
[2024-11-10T22:04:37.328+0000] {base.py:83} INFO - Using connection ID 'Postgres' for task execution.
[2024-11-10T22:04:37.331+0000] {sql.py:457} INFO - Running statement: insert into public.data (name, birth_date, age) values (Anna,2004-07-14,20), parameters: None
[2024-11-10T22:04:37.332+0000] {taskinstance.py:2731} ERROR - Task failed with exception
Traceback (most recent call last):
  File "/home/airflow/.local/lib/python3.8/site-packages/airflow/models/taskinstance.py", line 444, in _execute_task
    result = _execute_callable(context=context, **execute_callable_kwargs)
  File "/home/airflow/.local/lib/python3.8/site-packages/airflow/models/taskinstance.py", line 414, in _execute_callable
    return execute_callable(context=context, **execute_callable_kwargs)
  File "/home/airflow/.local/lib/python3.8/site-packages/airflow/decorators/base.py", line 241, in execute
    return_value = super().execute(context)
  File "/home/airflow/.local/lib/python3.8/site-packages/airflow/operators/python.py", line 200, in execute
    return_value = self.execute_callable()
  File "/home/airflow/.local/lib/python3.8/site-packages/airflow/operators/python.py", line 217, in execute_callable
    return self.python_callable(*self.op_args, **self.op_kwargs)
  File "/opt/airflow/dags/tasks_broker_postgres/load.py", line 15, in load
    hook.run(request)
  File "/home/airflow/.local/lib/python3.8/site-packages/airflow/providers/common/sql/hooks/sql.py", line 404, in run
    self._run_command(cur, sql_statement, parameters)
  File "/home/airflow/.local/lib/python3.8/site-packages/airflow/providers/common/sql/hooks/sql.py", line 462, in _run_command
    cur.execute(sql_statement)
psycopg2.errors.UndefinedColumn: column "anna" does not exist
LINE 1: ... into public.data (name, birth_date, age) values (Anna,2004-...
                                                             ^

[2024-11-10T22:04:37.340+0000] {taskinstance.py:1149} INFO - Marking task as FAILED. dag_id=python_broker_postgres, task_id=load, execution_date=20241110T220034, start_date=20241110T220437, end_date=20241110T220437
[2024-11-10T22:04:37.350+0000] {standard_task_runner.py:107} ERROR - Failed to execute job 1274 for task load (column "anna" does not exist
LINE 1: ... into public.data (name, birth_date, age) values (Anna,2004-...
                                                             ^
; 2524)
[2024-11-10T22:04:37.356+0000] {local_task_job_runner.py:234} INFO - Task exited with return code 1
[2024-11-10T22:04:37.368+0000] {taskinstance.py:3312} INFO - 0 downstream tasks scheduled from follow-on schedule check
